<?xml version="1.0"?>
<robot xmlns:xacro="http://www.ros.org/wiki/xacro">

  <!-- Properties -->
  <xacro:property name="chassis_length" value="0.8"/>
  <xacro:property name="chassis_width" value="0.6"/>
  <xacro:property name="chassis_height" value="0.15"/>
  <xacro:property name="chassis_mass" value="20.0"/>

  <xacro:property name="wheel_radius" value="0.1"/>
  <xacro:property name="wheel_width" value="0.05"/>
  <xacro:property name="wheel_mass" value="1.0"/>
  <xacro:property name="track_width" value="0.55"/>

  <xacro:property name="caster_radius" value="0.05"/>
  <xacro:property name="caster_mass" value="0.5"/>

  <!-- Inertia macros -->
  <xacro:macro name="box_inertia" params="m x y z">
    <inertial>
      <mass value="${m}"/>
      <inertia ixx="${m*(y*y+z*z)/12}" ixy="0" ixz="0"
               iyy="${m*(x*x+z*z)/12}" iyz="0"
               izz="${m*(x*x+y*y)/12}"/>
    </inertial>
  </xacro:macro>

  <xacro:macro name="cylinder_inertia" params="m r l">
    <inertial>
      <mass value="${m}"/>
      <inertia ixx="${m*(3*r*r+l*l)/12}" ixy="0" ixz="0"
               iyy="${m*(3*r*r+l*l)/12}" iyz="0"
               izz="${m*r*r/2}"/>
    </inertial>
  </xacro:macro>

  <xacro:macro name="sphere_inertia" params="m r">
    <inertial>
      <mass value="${m}"/>
      <inertia ixx="${2*m*r*r/5}" ixy="0" ixz="0"
               iyy="${2*m*r*r/5}" iyz="0"
               izz="${2*m*r*r/5}"/>
    </inertial>
  </xacro:macro>

  <!-- Base footprint (on the ground) -->
  <link name="base_footprint"/>

  <joint name="base_joint" type="fixed">
    <parent link="base_footprint"/>
    <child link="base_link"/>
    <origin xyz="0 0 ${wheel_radius}" rpy="0 0 0"/>
  </joint>

  <!-- Chassis -->
  <link name="base_link">
    <visual>
      <geometry>
        <box size="${chassis_length} ${chassis_width} ${chassis_height}"/>
      </geometry>
      <origin xyz="0 0 ${chassis_height/2}" rpy="0 0 0"/>
      <material name="blue"/>
    </visual>
    <collision>
      <geometry>
        <box size="${chassis_length} ${chassis_width} ${chassis_height}"/>
      </geometry>
      <origin xyz="0 0 ${chassis_height/2}" rpy="0 0 0"/>
    </collision>
    <xacro:box_inertia m="${chassis_mass}" x="${chassis_length}" y="${chassis_width}" z="${chassis_height}"/>
  </link>

  <!-- Wheel macro -->
  <xacro:macro name="drive_wheel" params="prefix y_offset">
    <link name="${prefix}_wheel_link">
      <visual>
        <geometry>
          <cylinder radius="${wheel_radius}" length="${wheel_width}"/>
        </geometry>
        <material name="dark_grey"/>
      </visual>
      <collision>
        <geometry>
          <cylinder radius="${wheel_radius}" length="${wheel_width}"/>
        </geometry>
        <surface>
          <friction>
            <ode>
              <mu>1.0</mu>
              <mu2>1.0</mu2>
            </ode>
          </friction>
        </surface>
      </collision>
      <xacro:cylinder_inertia m="${wheel_mass}" r="${wheel_radius}" l="${wheel_width}"/>
    </link>

    <joint name="${prefix}_wheel_joint" type="continuous">
      <parent link="base_link"/>
      <child link="${prefix}_wheel_link"/>
      <origin xyz="${-chassis_length/4} ${y_offset} 0" rpy="${-pi/2} 0 0"/>
      <axis xyz="0 0 1"/>
      <dynamics damping="0.1" friction="0.1"/>
    </joint>
  </xacro:macro>

  <xacro:drive_wheel prefix="left" y_offset="${track_width/2 + wheel_width/2}"/>
  <xacro:drive_wheel prefix="right" y_offset="${-(track_width/2 + wheel_width/2)}"/>

  <!-- Front caster -->
  <link name="caster_link">
    <visual>
      <geometry>
        <sphere radius="${caster_radius}"/>
      </geometry>
      <material name="light_grey"/>
    </visual>
    <collision>
      <geometry>
        <sphere radius="${caster_radius}"/>
      </geometry>
      <surface>
        <friction>
          <ode>
            <mu>0.01</mu>
            <mu2>0.01</mu2>
          </ode>
        </friction>
      </surface>
    </collision>
    <xacro:sphere_inertia m="${caster_mass}" r="${caster_radius}"/>
  </link>

  <joint name="caster_joint" type="fixed">
    <parent link="base_link"/>
    <child link="caster_link"/>
    <origin xyz="${chassis_length/3} 0 ${-(wheel_radius - caster_radius)}" rpy="0 0 0"/>
  </joint>

</robot>
